time: 2017-04-11 09:01:21.222180Z
tags: worker-0
test: unittest2.loader._FailedTest.tempest.tests.cmd.test_javelin
time: 2017-04-11 09:01:21.222340Z
failure: unittest2.loader._FailedTest.tempest.tests.cmd.test_javelin [ multipart
Content-Type: text/x-traceback;charset=utf8,language=python
traceback
223
Traceback (most recent call last):
ImportError: Failed to import test module: tempest.tests.cmd.test_javelin
Traceback (most recent call last):
  File "/root/tempest/.venv/lib/python2.7/site-packages/unittest2/loader.py", line 456, in _find_test_path
    module = self._get_module_from_name(name)
  File "/root/tempest/.venv/lib/python2.7/site-packages/unittest2/loader.py", line 395, in _get_module_from_name
    __import__(name)
  File "tempest/tests/cmd/test_javelin.py", line 15, in <module>
    import mock
ImportError: No module named mock

0
]
tags: -worker-0
time: 2017-04-11 09:01:21.222893Z
tags: worker-0
test: unittest2.loader._FailedTest.tempest.tests.cmd.test_tempest_init
time: 2017-04-11 09:01:21.223009Z
failure: unittest2.loader._FailedTest.tempest.tests.cmd.test_tempest_init [ multipart
Content-Type: text/x-traceback;charset=utf8,language=python
traceback
29D
Traceback (most recent call last):
ImportError: Failed to import test module: tempest.tests.cmd.test_tempest_init
Traceback (most recent call last):
  File "/root/tempest/.venv/lib/python2.7/site-packages/unittest2/loader.py", line 456, in _find_test_path
    module = self._get_module_from_name(name)
  File "/root/tempest/.venv/lib/python2.7/site-packages/unittest2/loader.py", line 395, in _get_module_from_name
    __import__(name)
  File "tempest/tests/cmd/test_tempest_init.py", line 20, in <module>
    from tempest.cmd import init
  File "tempest/cmd/init.py", line 21, in <module>
    from oslo_log import log as logging
ImportError: No module named oslo_log

0
]
tags: -worker-0
time: 2017-04-11 09:01:21.223352Z
tags: worker-0
test: unittest2.loader._FailedTest.tempest.tests.cmd.test_verify_tempest_config
time: 2017-04-11 09:01:21.223459Z
failure: unittest2.loader._FailedTest.tempest.tests.cmd.test_verify_tempest_config [ multipart
Content-Type: text/x-traceback;charset=utf8,language=python
traceback
23F
Traceback (most recent call last):
ImportError: Failed to import test module: tempest.tests.cmd.test_verify_tempest_config
Traceback (most recent call last):
  File "/root/tempest/.venv/lib/python2.7/site-packages/unittest2/loader.py", line 456, in _find_test_path
    module = self._get_module_from_name(name)
  File "/root/tempest/.venv/lib/python2.7/site-packages/unittest2/loader.py", line 395, in _get_module_from_name
    __import__(name)
  File "tempest/tests/cmd/test_verify_tempest_config.py", line 16, in <module>
    import mock
ImportError: No module named mock

0
]
tags: -worker-0
time: 2017-04-11 09:01:21.223799Z
tags: worker-0
test: unittest2.loader._FailedTest.tempest.tests.common.test_admin_available
time: 2017-04-11 09:01:21.223922Z
failure: unittest2.loader._FailedTest.tempest.tests.common.test_admin_available [ multipart
Content-Type: text/x-traceback;charset=utf8,language=python
traceback
250
Traceback (most recent call last):
ImportError: Failed to import test module: tempest.tests.common.test_admin_available
Traceback (most recent call last):
  File "/root/tempest/.venv/lib/python2.7/site-packages/unittest2/loader.py", line 456, in _find_test_path
    module = self._get_module_from_name(name)
  File "/root/tempest/.venv/lib/python2.7/site-packages/unittest2/loader.py", line 395, in _get_module_from_name
    __import__(name)
  File "tempest/tests/common/test_admin_available.py", line 15, in <module>
    from oslo_config import cfg
ImportError: No module named oslo_config

0
]
tags: -worker-0
time: 2017-04-11 09:01:21.224252Z
tags: worker-0
test: unittest2.loader._FailedTest.tempest.tests.common.test_cred_provider
time: 2017-04-11 09:01:21.224352Z
failure: unittest2.loader._FailedTest.tempest.tests.common.test_cred_provider [ multipart
Content-Type: text/x-traceback;charset=utf8,language=python
traceback
24C
Traceback (most recent call last):
ImportError: Failed to import test module: tempest.tests.common.test_cred_provider
Traceback (most recent call last):
  File "/root/tempest/.venv/lib/python2.7/site-packages/unittest2/loader.py", line 456, in _find_test_path
    module = self._get_module_from_name(name)
  File "/root/tempest/.venv/lib/python2.7/site-packages/unittest2/loader.py", line 395, in _get_module_from_name
    __import__(name)
  File "tempest/tests/common/test_cred_provider.py", line 15, in <module>
    from oslo_config import cfg
ImportError: No module named oslo_config

0
]
tags: -worker-0
time: 2017-04-11 09:01:21.224698Z
tags: worker-0
test: unittest2.loader._FailedTest.tempest.tests.common.test_custom_matchers
time: 2017-04-11 09:01:21.224800Z
failure: unittest2.loader._FailedTest.tempest.tests.common.test_custom_matchers [ multipart
Content-Type: text/x-traceback;charset=utf8,language=python
traceback
291
Traceback (most recent call last):
ImportError: Failed to import test module: tempest.tests.common.test_custom_matchers
Traceback (most recent call last):
  File "/root/tempest/.venv/lib/python2.7/site-packages/unittest2/loader.py", line 456, in _find_test_path
    module = self._get_module_from_name(name)
  File "/root/tempest/.venv/lib/python2.7/site-packages/unittest2/loader.py", line 395, in _get_module_from_name
    __import__(name)
  File "tempest/tests/common/test_custom_matchers.py", line 17, in <module>
    from tempest.tests import base
  File "tempest/tests/base.py", line 15, in <module>
    import mock
ImportError: No module named mock

0
]
tags: -worker-0
time: 2017-04-11 09:01:21.225145Z
tags: worker-0
test: unittest2.loader._FailedTest.tempest.tests.common.test_preprov_creds
time: 2017-04-11 09:01:21.225249Z
failure: unittest2.loader._FailedTest.tempest.tests.common.test_preprov_creds [ multipart
Content-Type: text/x-traceback;charset=utf8,language=python
traceback
235
Traceback (most recent call last):
ImportError: Failed to import test module: tempest.tests.common.test_preprov_creds
Traceback (most recent call last):
  File "/root/tempest/.venv/lib/python2.7/site-packages/unittest2/loader.py", line 456, in _find_test_path
    module = self._get_module_from_name(name)
  File "/root/tempest/.venv/lib/python2.7/site-packages/unittest2/loader.py", line 395, in _get_module_from_name
    __import__(name)
  File "tempest/tests/common/test_preprov_creds.py", line 18, in <module>
    import mock
ImportError: No module named mock

0
]
tags: -worker-0
time: 2017-04-11 09:01:21.225570Z
tags: worker-0
test: unittest2.loader._FailedTest.tempest.tests.common.test_service_clients
time: 2017-04-11 09:01:21.225673Z
failure: unittest2.loader._FailedTest.tempest.tests.common.test_service_clients [ multipart
Content-Type: text/x-traceback;charset=utf8,language=python
traceback
239
Traceback (most recent call last):
ImportError: Failed to import test module: tempest.tests.common.test_service_clients
Traceback (most recent call last):
  File "/root/tempest/.venv/lib/python2.7/site-packages/unittest2/loader.py", line 456, in _find_test_path
    module = self._get_module_from_name(name)
  File "/root/tempest/.venv/lib/python2.7/site-packages/unittest2/loader.py", line 395, in _get_module_from_name
    __import__(name)
  File "tempest/tests/common/test_service_clients.py", line 15, in <module>
    import mock
ImportError: No module named mock

0
]
tags: -worker-0
time: 2017-04-11 09:01:21.226016Z
tags: worker-0
test: unittest2.loader._FailedTest.tempest.tests.common.test_waiters
time: 2017-04-11 09:01:21.226126Z
failure: unittest2.loader._FailedTest.tempest.tests.common.test_waiters [ multipart
Content-Type: text/x-traceback;charset=utf8,language=python
traceback
229
Traceback (most recent call last):
ImportError: Failed to import test module: tempest.tests.common.test_waiters
Traceback (most recent call last):
  File "/root/tempest/.venv/lib/python2.7/site-packages/unittest2/loader.py", line 456, in _find_test_path
    module = self._get_module_from_name(name)
  File "/root/tempest/.venv/lib/python2.7/site-packages/unittest2/loader.py", line 395, in _get_module_from_name
    __import__(name)
  File "tempest/tests/common/test_waiters.py", line 17, in <module>
    import mock
ImportError: No module named mock

0
]
tags: -worker-0
time: 2017-04-11 09:01:21.226483Z
tags: worker-0
test: unittest2.loader._FailedTest.tempest.tests.common.utils.linux.test_remote_client
time: 2017-04-11 09:01:21.226595Z
failure: unittest2.loader._FailedTest.tempest.tests.common.utils.linux.test_remote_client [ multipart
Content-Type: text/x-traceback;charset=utf8,language=python
traceback
264
Traceback (most recent call last):
ImportError: Failed to import test module: tempest.tests.common.utils.linux.test_remote_client
Traceback (most recent call last):
  File "/root/tempest/.venv/lib/python2.7/site-packages/unittest2/loader.py", line 456, in _find_test_path
    module = self._get_module_from_name(name)
  File "/root/tempest/.venv/lib/python2.7/site-packages/unittest2/loader.py", line 395, in _get_module_from_name
    __import__(name)
  File "tempest/tests/common/utils/linux/test_remote_client.py", line 17, in <module>
    from oslo_config import cfg
ImportError: No module named oslo_config

0
]
tags: -worker-0
time: 2017-04-11 09:01:21.226961Z
tags: worker-0
test: unittest2.loader._FailedTest.tempest.tests.common.utils.test_file_utils
time: 2017-04-11 09:01:21.227062Z
failure: unittest2.loader._FailedTest.tempest.tests.common.utils.test_file_utils [ multipart
Content-Type: text/x-traceback;charset=utf8,language=python
traceback
23B
Traceback (most recent call last):
ImportError: Failed to import test module: tempest.tests.common.utils.test_file_utils
Traceback (most recent call last):
  File "/root/tempest/.venv/lib/python2.7/site-packages/unittest2/loader.py", line 456, in _find_test_path
    module = self._get_module_from_name(name)
  File "/root/tempest/.venv/lib/python2.7/site-packages/unittest2/loader.py", line 395, in _get_module_from_name
    __import__(name)
  File "tempest/tests/common/utils/test_file_utils.py", line 16, in <module>
    import mock
ImportError: No module named mock

0
]
tags: -worker-0
time: 2017-04-11 09:01:21.227404Z
tags: worker-0
test: unittest2.loader._FailedTest.tempest.tests.negative.test_negative_auto_test
time: 2017-04-11 09:01:21.227508Z
failure: unittest2.loader._FailedTest.tempest.tests.negative.test_negative_auto_test [ multipart
Content-Type: text/x-traceback;charset=utf8,language=python
traceback
2AA
Traceback (most recent call last):
ImportError: Failed to import test module: tempest.tests.negative.test_negative_auto_test
Traceback (most recent call last):
  File "/root/tempest/.venv/lib/python2.7/site-packages/unittest2/loader.py", line 456, in _find_test_path
    module = self._get_module_from_name(name)
  File "/root/tempest/.venv/lib/python2.7/site-packages/unittest2/loader.py", line 395, in _get_module_from_name
    __import__(name)
  File "tempest/tests/negative/test_negative_auto_test.py", line 16, in <module>
    from tempest import config
  File "tempest/config.py", line 21, in <module>
    from oslo_config import cfg
ImportError: No module named oslo_config

0
]
tags: -worker-0
time: 2017-04-11 09:01:21.227849Z
tags: worker-0
test: unittest2.loader._FailedTest.tempest.tests.negative.test_negative_generators
time: 2017-04-11 09:01:21.227957Z
failure: unittest2.loader._FailedTest.tempest.tests.negative.test_negative_generators [ multipart
Content-Type: text/x-traceback;charset=utf8,language=python
traceback
245
Traceback (most recent call last):
ImportError: Failed to import test module: tempest.tests.negative.test_negative_generators
Traceback (most recent call last):
  File "/root/tempest/.venv/lib/python2.7/site-packages/unittest2/loader.py", line 456, in _find_test_path
    module = self._get_module_from_name(name)
  File "/root/tempest/.venv/lib/python2.7/site-packages/unittest2/loader.py", line 395, in _get_module_from_name
    __import__(name)
  File "tempest/tests/negative/test_negative_generators.py", line 19, in <module>
    import mock
ImportError: No module named mock

0
]
tags: -worker-0
time: 2017-04-11 09:01:21.228294Z
tags: worker-0
test: unittest2.loader._FailedTest.tempest.tests.services.compute.test_fixedIPs_client
time: 2017-04-11 09:01:21.228395Z
failure: unittest2.loader._FailedTest.tempest.tests.services.compute.test_fixedIPs_client [ multipart
Content-Type: text/x-traceback;charset=utf8,language=python
traceback
27F
Traceback (most recent call last):
ImportError: Failed to import test module: tempest.tests.services.compute.test_fixedIPs_client
Traceback (most recent call last):
  File "/root/tempest/.venv/lib/python2.7/site-packages/unittest2/loader.py", line 456, in _find_test_path
    module = self._get_module_from_name(name)
  File "/root/tempest/.venv/lib/python2.7/site-packages/unittest2/loader.py", line 395, in _get_module_from_name
    __import__(name)
  File "tempest/tests/services/compute/test_fixedIPs_client.py", line 15, in <module>
    from tempest_lib.tests import fake_auth_provider
ImportError: No module named tempest_lib.tests

0
]
tags: -worker-0
time: 2017-04-11 09:01:21.228724Z
tags: worker-0
test: unittest2.loader._FailedTest.tempest.tests.services.compute.test_flavors_client
time: 2017-04-11 09:01:21.228824Z
failure: unittest2.loader._FailedTest.tempest.tests.services.compute.test_flavors_client [ multipart
Content-Type: text/x-traceback;charset=utf8,language=python
traceback
27E
Traceback (most recent call last):
ImportError: Failed to import test module: tempest.tests.services.compute.test_flavors_client
Traceback (most recent call last):
  File "/root/tempest/.venv/lib/python2.7/site-packages/unittest2/loader.py", line 456, in _find_test_path
    module = self._get_module_from_name(name)
  File "/root/tempest/.venv/lib/python2.7/site-packages/unittest2/loader.py", line 395, in _get_module_from_name
    __import__(name)
  File "tempest/tests/services/compute/test_flavors_client.py", line 18, in <module>
    from oslo_serialization import jsonutils as json
ImportError: No module named oslo_serialization

0
]
tags: -worker-0
time: 2017-04-11 09:01:21.229161Z
tags: worker-0
test: unittest2.loader._FailedTest.tempest.tests.services.compute.test_floating_ip_pools_client
time: 2017-04-11 09:01:21.229262Z
failure: unittest2.loader._FailedTest.tempest.tests.services.compute.test_floating_ip_pools_client [ multipart
Content-Type: text/x-traceback;charset=utf8,language=python
traceback
291
Traceback (most recent call last):
ImportError: Failed to import test module: tempest.tests.services.compute.test_floating_ip_pools_client
Traceback (most recent call last):
  File "/root/tempest/.venv/lib/python2.7/site-packages/unittest2/loader.py", line 456, in _find_test_path
    module = self._get_module_from_name(name)
  File "/root/tempest/.venv/lib/python2.7/site-packages/unittest2/loader.py", line 395, in _get_module_from_name
    __import__(name)
  File "tempest/tests/services/compute/test_floating_ip_pools_client.py", line 15, in <module>
    from tempest_lib.tests import fake_auth_provider
ImportError: No module named tempest_lib.tests

0
]
tags: -worker-0
time: 2017-04-11 09:01:21.229587Z
tags: worker-0
test: unittest2.loader._FailedTest.tempest.tests.services.compute.test_floating_ips_bulk_client
time: 2017-04-11 09:01:21.229687Z
failure: unittest2.loader._FailedTest.tempest.tests.services.compute.test_floating_ips_bulk_client [ multipart
Content-Type: text/x-traceback;charset=utf8,language=python
traceback
291
Traceback (most recent call last):
ImportError: Failed to import test module: tempest.tests.services.compute.test_floating_ips_bulk_client
Traceback (most recent call last):
  File "/root/tempest/.venv/lib/python2.7/site-packages/unittest2/loader.py", line 456, in _find_test_path
    module = self._get_module_from_name(name)
  File "/root/tempest/.venv/lib/python2.7/site-packages/unittest2/loader.py", line 395, in _get_module_from_name
    __import__(name)
  File "tempest/tests/services/compute/test_floating_ips_bulk_client.py", line 15, in <module>
    from tempest_lib.tests import fake_auth_provider
ImportError: No module named tempest_lib.tests

0
]
tags: -worker-0
time: 2017-04-11 09:01:21.230034Z
tags: worker-0
test: unittest2.loader._FailedTest.tempest.tests.services.compute.test_floating_ips_client
time: 2017-04-11 09:01:21.230134Z
failure: unittest2.loader._FailedTest.tempest.tests.services.compute.test_floating_ips_client [ multipart
Content-Type: text/x-traceback;charset=utf8,language=python
traceback
26C
Traceback (most recent call last):
ImportError: Failed to import test module: tempest.tests.services.compute.test_floating_ips_client
Traceback (most recent call last):
  File "/root/tempest/.venv/lib/python2.7/site-packages/unittest2/loader.py", line 456, in _find_test_path
    module = self._get_module_from_name(name)
  File "/root/tempest/.venv/lib/python2.7/site-packages/unittest2/loader.py", line 395, in _get_module_from_name
    __import__(name)
  File "tempest/tests/services/compute/test_floating_ips_client.py", line 15, in <module>
    from oslotest import mockpatch
ImportError: No module named oslotest

0
]
tags: -worker-0
time: 2017-04-11 09:01:21.230454Z
tags: worker-0
test: unittest2.loader._FailedTest.tempest.tests.services.compute.test_hosts_client
time: 2017-04-11 09:01:21.230554Z
failure: unittest2.loader._FailedTest.tempest.tests.services.compute.test_hosts_client [ multipart
Content-Type: text/x-traceback;charset=utf8,language=python
traceback
302
Traceback (most recent call last):
ImportError: Failed to import test module: tempest.tests.services.compute.test_hosts_client
Traceback (most recent call last):
  File "/root/tempest/.venv/lib/python2.7/site-packages/unittest2/loader.py", line 456, in _find_test_path
    module = self._get_module_from_name(name)
  File "/root/tempest/.venv/lib/python2.7/site-packages/unittest2/loader.py", line 395, in _get_module_from_name
    __import__(name)
  File "tempest/tests/services/compute/test_hosts_client.py", line 15, in <module>
    from tempest.services.compute.json import hosts_client
  File "tempest/services/compute/json/hosts_client.py", line 15, in <module>
    from oslo_serialization import jsonutils as json
ImportError: No module named oslo_serialization

0
]
tags: -worker-0
time: 2017-04-11 09:01:21.230909Z
tags: worker-0
test: unittest2.loader._FailedTest.tempest.tests.services.compute.test_hypervisor_client
time: 2017-04-11 09:01:21.231017Z
failure: unittest2.loader._FailedTest.tempest.tests.services.compute.test_hypervisor_client [ multipart
Content-Type: text/x-traceback;charset=utf8,language=python
traceback
316
Traceback (most recent call last):
ImportError: Failed to import test module: tempest.tests.services.compute.test_hypervisor_client
Traceback (most recent call last):
  File "/root/tempest/.venv/lib/python2.7/site-packages/unittest2/loader.py", line 456, in _find_test_path
    module = self._get_module_from_name(name)
  File "/root/tempest/.venv/lib/python2.7/site-packages/unittest2/loader.py", line 395, in _get_module_from_name
    __import__(name)
  File "tempest/tests/services/compute/test_hypervisor_client.py", line 15, in <module>
    from tempest.services.compute.json import hypervisor_client
  File "tempest/services/compute/json/hypervisor_client.py", line 16, in <module>
    from oslo_serialization import jsonutils as json
ImportError: No module named oslo_serialization

0
]
tags: -worker-0
time: 2017-04-11 09:01:21.231350Z
tags: worker-0
test: unittest2.loader._FailedTest.tempest.tests.services.compute.test_images_client
time: 2017-04-11 09:01:21.231453Z
failure: unittest2.loader._FailedTest.tempest.tests.services.compute.test_images_client [ multipart
Content-Type: text/x-traceback;charset=utf8,language=python
traceback
260
Traceback (most recent call last):
ImportError: Failed to import test module: tempest.tests.services.compute.test_images_client
Traceback (most recent call last):
  File "/root/tempest/.venv/lib/python2.7/site-packages/unittest2/loader.py", line 456, in _find_test_path
    module = self._get_module_from_name(name)
  File "/root/tempest/.venv/lib/python2.7/site-packages/unittest2/loader.py", line 395, in _get_module_from_name
    __import__(name)
  File "tempest/tests/services/compute/test_images_client.py", line 17, in <module>
    from oslotest import mockpatch
ImportError: No module named oslotest

0
]
tags: -worker-0
time: 2017-04-11 09:01:21.231774Z
tags: worker-0
test: unittest2.loader._FailedTest.tempest.tests.services.compute.test_instance_usage_audit_log_client
time: 2017-04-11 09:01:21.277032Z
failure: unittest2.loader._FailedTest.tempest.tests.services.compute.test_instance_usage_audit_log_client [ multipart
Content-Type: text/x-traceback;charset=utf8,language=python
traceback
29F
Traceback (most recent call last):
ImportError: Failed to import test module: tempest.tests.services.compute.test_instance_usage_audit_log_client
Traceback (most recent call last):
  File "/root/tempest/.venv/lib/python2.7/site-packages/unittest2/loader.py", line 456, in _find_test_path
    module = self._get_module_from_name(name)
  File "/root/tempest/.venv/lib/python2.7/site-packages/unittest2/loader.py", line 395, in _get_module_from_name
    __import__(name)
  File "tempest/tests/services/compute/test_instance_usage_audit_log_client.py", line 17, in <module>
    from tempest_lib.tests import fake_auth_provider
ImportError: No module named tempest_lib.tests

0
]
tags: -worker-0
time: 2017-04-11 09:01:21.277504Z
tags: worker-0
test: unittest2.loader._FailedTest.tempest.tests.services.compute.test_interfaces_client
time: 2017-04-11 09:01:21.277619Z
failure: unittest2.loader._FailedTest.tempest.tests.services.compute.test_interfaces_client [ multipart
Content-Type: text/x-traceback;charset=utf8,language=python
traceback
316
Traceback (most recent call last):
ImportError: Failed to import test module: tempest.tests.services.compute.test_interfaces_client
Traceback (most recent call last):
  File "/root/tempest/.venv/lib/python2.7/site-packages/unittest2/loader.py", line 456, in _find_test_path
    module = self._get_module_from_name(name)
  File "/root/tempest/.venv/lib/python2.7/site-packages/unittest2/loader.py", line 395, in _get_module_from_name
    __import__(name)
  File "tempest/tests/services/compute/test_interfaces_client.py", line 15, in <module>
    from tempest.services.compute.json import interfaces_client
  File "tempest/services/compute/json/interfaces_client.py", line 16, in <module>
    from oslo_serialization import jsonutils as json
ImportError: No module named oslo_serialization

0
]
tags: -worker-0
time: 2017-04-11 09:01:21.277997Z
tags: worker-0
test: unittest2.loader._FailedTest.tempest.tests.services.compute.test_keypairs_client
time: 2017-04-11 09:01:21.278106Z
failure: unittest2.loader._FailedTest.tempest.tests.services.compute.test_keypairs_client [ multipart
Content-Type: text/x-traceback;charset=utf8,language=python
traceback
27F
Traceback (most recent call last):
ImportError: Failed to import test module: tempest.tests.services.compute.test_keypairs_client
Traceback (most recent call last):
  File "/root/tempest/.venv/lib/python2.7/site-packages/unittest2/loader.py", line 456, in _find_test_path
    module = self._get_module_from_name(name)
  File "/root/tempest/.venv/lib/python2.7/site-packages/unittest2/loader.py", line 395, in _get_module_from_name
    __import__(name)
  File "tempest/tests/services/compute/test_keypairs_client.py", line 17, in <module>
    from tempest_lib.tests import fake_auth_provider
ImportError: No module named tempest_lib.tests

0
]
tags: -worker-0
time: 2017-04-11 09:01:21.278445Z
tags: worker-0
test: unittest2.loader._FailedTest.tempest.tests.services.compute.test_limits_client
time: 2017-04-11 09:01:21.278551Z
failure: unittest2.loader._FailedTest.tempest.tests.services.compute.test_limits_client [ multipart
Content-Type: text/x-traceback;charset=utf8,language=python
traceback
27B
Traceback (most recent call last):
ImportError: Failed to import test module: tempest.tests.services.compute.test_limits_client
Traceback (most recent call last):
  File "/root/tempest/.venv/lib/python2.7/site-packages/unittest2/loader.py", line 456, in _find_test_path
    module = self._get_module_from_name(name)
  File "/root/tempest/.venv/lib/python2.7/site-packages/unittest2/loader.py", line 395, in _get_module_from_name
    __import__(name)
  File "tempest/tests/services/compute/test_limits_client.py", line 15, in <module>
    from tempest_lib.tests import fake_auth_provider
ImportError: No module named tempest_lib.tests

0
]
tags: -worker-0
time: 2017-04-11 09:01:21.278905Z
tags: worker-0
test: unittest2.loader._FailedTest.tempest.tests.services.compute.test_migrations_client
time: 2017-04-11 09:01:21.279008Z
failure: unittest2.loader._FailedTest.tempest.tests.services.compute.test_migrations_client [ multipart
Content-Type: text/x-traceback;charset=utf8,language=python
traceback
283
Traceback (most recent call last):
ImportError: Failed to import test module: tempest.tests.services.compute.test_migrations_client
Traceback (most recent call last):
  File "/root/tempest/.venv/lib/python2.7/site-packages/unittest2/loader.py", line 456, in _find_test_path
    module = self._get_module_from_name(name)
  File "/root/tempest/.venv/lib/python2.7/site-packages/unittest2/loader.py", line 395, in _get_module_from_name
    __import__(name)
  File "tempest/tests/services/compute/test_migrations_client.py", line 15, in <module>
    from tempest_lib.tests import fake_auth_provider
ImportError: No module named tempest_lib.tests

0
]
tags: -worker-0
time: 2017-04-11 09:01:21.279351Z
tags: worker-0
test: unittest2.loader._FailedTest.tempest.tests.services.compute.test_networks_client
time: 2017-04-11 09:01:21.279454Z
failure: unittest2.loader._FailedTest.tempest.tests.services.compute.test_networks_client [ multipart
Content-Type: text/x-traceback;charset=utf8,language=python
traceback
27F
Traceback (most recent call last):
ImportError: Failed to import test module: tempest.tests.services.compute.test_networks_client
Traceback (most recent call last):
  File "/root/tempest/.venv/lib/python2.7/site-packages/unittest2/loader.py", line 456, in _find_test_path
    module = self._get_module_from_name(name)
  File "/root/tempest/.venv/lib/python2.7/site-packages/unittest2/loader.py", line 395, in _get_module_from_name
    __import__(name)
  File "tempest/tests/services/compute/test_networks_client.py", line 15, in <module>
    from tempest_lib.tests import fake_auth_provider
ImportError: No module named tempest_lib.tests

0
]
tags: -worker-0
time: 2017-04-11 09:01:21.279787Z
tags: worker-0
test: unittest2.loader._FailedTest.tempest.tests.services.compute.test_quota_classes_client
time: 2017-04-11 09:01:21.279903Z
failure: unittest2.loader._FailedTest.tempest.tests.services.compute.test_quota_classes_client [ multipart
Content-Type: text/x-traceback;charset=utf8,language=python
traceback
289
Traceback (most recent call last):
ImportError: Failed to import test module: tempest.tests.services.compute.test_quota_classes_client
Traceback (most recent call last):
  File "/root/tempest/.venv/lib/python2.7/site-packages/unittest2/loader.py", line 456, in _find_test_path
    module = self._get_module_from_name(name)
  File "/root/tempest/.venv/lib/python2.7/site-packages/unittest2/loader.py", line 395, in _get_module_from_name
    __import__(name)
  File "tempest/tests/services/compute/test_quota_classes_client.py", line 17, in <module>
    from tempest_lib.tests import fake_auth_provider
ImportError: No module named tempest_lib.tests

0
]
tags: -worker-0
time: 2017-04-11 09:01:21.280239Z
tags: worker-0
test: unittest2.loader._FailedTest.tempest.tests.services.compute.test_quotas_client
time: 2017-04-11 09:01:21.280341Z
failure: unittest2.loader._FailedTest.tempest.tests.services.compute.test_quotas_client [ multipart
Content-Type: text/x-traceback;charset=utf8,language=python
traceback
27B
Traceback (most recent call last):
ImportError: Failed to import test module: tempest.tests.services.compute.test_quotas_client
Traceback (most recent call last):
  File "/root/tempest/.venv/lib/python2.7/site-packages/unittest2/loader.py", line 456, in _find_test_path
    module = self._get_module_from_name(name)
  File "/root/tempest/.venv/lib/python2.7/site-packages/unittest2/loader.py", line 395, in _get_module_from_name
    __import__(name)
  File "tempest/tests/services/compute/test_quotas_client.py", line 17, in <module>
    from tempest_lib.tests import fake_auth_provider
ImportError: No module named tempest_lib.tests

0
]
tags: -worker-0
time: 2017-04-11 09:01:21.280675Z
tags: worker-0
test: unittest2.loader._FailedTest.tempest.tests.services.compute.test_security_group_default_rules_client
time: 2017-04-11 09:01:21.280776Z
failure: unittest2.loader._FailedTest.tempest.tests.services.compute.test_security_group_default_rules_client [ multipart
Content-Type: text/x-traceback;charset=utf8,language=python
traceback
2A7
Traceback (most recent call last):
ImportError: Failed to import test module: tempest.tests.services.compute.test_security_group_default_rules_client
Traceback (most recent call last):
  File "/root/tempest/.venv/lib/python2.7/site-packages/unittest2/loader.py", line 456, in _find_test_path
    module = self._get_module_from_name(name)
  File "/root/tempest/.venv/lib/python2.7/site-packages/unittest2/loader.py", line 395, in _get_module_from_name
    __import__(name)
  File "tempest/tests/services/compute/test_security_group_default_rules_client.py", line 15, in <module>
    from tempest_lib.tests import fake_auth_provider
ImportError: No module named tempest_lib.tests

0
]
tags: -worker-0
time: 2017-04-11 09:01:21.281123Z
tags: worker-0
test: unittest2.loader._FailedTest.tempest.tests.services.compute.test_security_group_rules_client
time: 2017-04-11 09:01:21.281225Z
failure: unittest2.loader._FailedTest.tempest.tests.services.compute.test_security_group_rules_client [ multipart
Content-Type: text/x-traceback;charset=utf8,language=python
traceback
33E
Traceback (most recent call last):
ImportError: Failed to import test module: tempest.tests.services.compute.test_security_group_rules_client
Traceback (most recent call last):
  File "/root/tempest/.venv/lib/python2.7/site-packages/unittest2/loader.py", line 456, in _find_test_path
    module = self._get_module_from_name(name)
  File "/root/tempest/.venv/lib/python2.7/site-packages/unittest2/loader.py", line 395, in _get_module_from_name
    __import__(name)
  File "tempest/tests/services/compute/test_security_group_rules_client.py", line 15, in <module>
    from tempest.services.compute.json import security_group_rules_client
  File "tempest/services/compute/json/security_group_rules_client.py", line 16, in <module>
    from oslo_serialization import jsonutils as json
ImportError: No module named oslo_serialization

0
]
tags: -worker-0
time: 2017-04-11 09:01:21.281554Z
tags: worker-0
test: unittest2.loader._FailedTest.tempest.tests.services.compute.test_security_groups_client
time: 2017-04-11 09:01:21.281655Z
failure: unittest2.loader._FailedTest.tempest.tests.services.compute.test_security_groups_client [ multipart
Content-Type: text/x-traceback;charset=utf8,language=python
traceback
272
Traceback (most recent call last):
ImportError: Failed to import test module: tempest.tests.services.compute.test_security_groups_client
Traceback (most recent call last):
  File "/root/tempest/.venv/lib/python2.7/site-packages/unittest2/loader.py", line 456, in _find_test_path
    module = self._get_module_from_name(name)
  File "/root/tempest/.venv/lib/python2.7/site-packages/unittest2/loader.py", line 395, in _get_module_from_name
    __import__(name)
  File "tempest/tests/services/compute/test_security_groups_client.py", line 15, in <module>
    from oslotest import mockpatch
ImportError: No module named oslotest

0
]
tags: -worker-0
time: 2017-04-11 09:01:21.281999Z
tags: worker-0
test: unittest2.loader._FailedTest.tempest.tests.services.compute.test_server_groups_client
time: 2017-04-11 09:01:21.282101Z
failure: unittest2.loader._FailedTest.tempest.tests.services.compute.test_server_groups_client [ multipart
Content-Type: text/x-traceback;charset=utf8,language=python
traceback
26E
Traceback (most recent call last):
ImportError: Failed to import test module: tempest.tests.services.compute.test_server_groups_client
Traceback (most recent call last):
  File "/root/tempest/.venv/lib/python2.7/site-packages/unittest2/loader.py", line 456, in _find_test_path
    module = self._get_module_from_name(name)
  File "/root/tempest/.venv/lib/python2.7/site-packages/unittest2/loader.py", line 395, in _get_module_from_name
    __import__(name)
  File "tempest/tests/services/compute/test_server_groups_client.py", line 17, in <module>
    from oslotest import mockpatch
ImportError: No module named oslotest

0
]
tags: -worker-0
time: 2017-04-11 09:01:21.282422Z
tags: worker-0
test: unittest2.loader._FailedTest.tempest.tests.services.compute.test_servers_client
time: 2017-04-11 09:01:21.282523Z
failure: unittest2.loader._FailedTest.tempest.tests.services.compute.test_servers_client [ multipart
Content-Type: text/x-traceback;charset=utf8,language=python
traceback
30A
Traceback (most recent call last):
ImportError: Failed to import test module: tempest.tests.services.compute.test_servers_client
Traceback (most recent call last):
  File "/root/tempest/.venv/lib/python2.7/site-packages/unittest2/loader.py", line 456, in _find_test_path
    module = self._get_module_from_name(name)
  File "/root/tempest/.venv/lib/python2.7/site-packages/unittest2/loader.py", line 395, in _get_module_from_name
    __import__(name)
  File "tempest/tests/services/compute/test_servers_client.py", line 15, in <module>
    from tempest.services.compute.json import servers_client
  File "tempest/services/compute/json/servers_client.py", line 19, in <module>
    from oslo_serialization import jsonutils as json
ImportError: No module named oslo_serialization

0
]
tags: -worker-0
time: 2017-04-11 09:01:21.282865Z
tags: worker-0
test: unittest2.loader._FailedTest.tempest.tests.services.compute.test_services_client
time: 2017-04-11 09:01:21.282968Z
failure: unittest2.loader._FailedTest.tempest.tests.services.compute.test_services_client [ multipart
Content-Type: text/x-traceback;charset=utf8,language=python
traceback
27F
Traceback (most recent call last):
ImportError: Failed to import test module: tempest.tests.services.compute.test_services_client
Traceback (most recent call last):
  File "/root/tempest/.venv/lib/python2.7/site-packages/unittest2/loader.py", line 456, in _find_test_path
    module = self._get_module_from_name(name)
  File "/root/tempest/.venv/lib/python2.7/site-packages/unittest2/loader.py", line 395, in _get_module_from_name
    __import__(name)
  File "tempest/tests/services/compute/test_services_client.py", line 17, in <module>
    from tempest_lib.tests import fake_auth_provider
ImportError: No module named tempest_lib.tests

0
]
tags: -worker-0
time: 2017-04-11 09:01:21.283289Z
tags: worker-0
test: unittest2.loader._FailedTest.tempest.tests.services.compute.test_snapshots_client
time: 2017-04-11 09:01:21.283389Z
failure: unittest2.loader._FailedTest.tempest.tests.services.compute.test_snapshots_client [ multipart
Content-Type: text/x-traceback;charset=utf8,language=python
traceback
266
Traceback (most recent call last):
ImportError: Failed to import test module: tempest.tests.services.compute.test_snapshots_client
Traceback (most recent call last):
  File "/root/tempest/.venv/lib/python2.7/site-packages/unittest2/loader.py", line 456, in _find_test_path
    module = self._get_module_from_name(name)
  File "/root/tempest/.venv/lib/python2.7/site-packages/unittest2/loader.py", line 395, in _get_module_from_name
    __import__(name)
  File "tempest/tests/services/compute/test_snapshots_client.py", line 15, in <module>
    from oslotest import mockpatch
ImportError: No module named oslotest

0
]
tags: -worker-0
time: 2017-04-11 09:01:21.283709Z
tags: worker-0
test: unittest2.loader._FailedTest.tempest.tests.services.compute.test_tenant_networks_client
time: 2017-04-11 09:01:21.283809Z
failure: unittest2.loader._FailedTest.tempest.tests.services.compute.test_tenant_networks_client [ multipart
Content-Type: text/x-traceback;charset=utf8,language=python
traceback
28D
Traceback (most recent call last):
ImportError: Failed to import test module: tempest.tests.services.compute.test_tenant_networks_client
Traceback (most recent call last):
  File "/root/tempest/.venv/lib/python2.7/site-packages/unittest2/loader.py", line 456, in _find_test_path
    module = self._get_module_from_name(name)
  File "/root/tempest/.venv/lib/python2.7/site-packages/unittest2/loader.py", line 395, in _get_module_from_name
    __import__(name)
  File "tempest/tests/services/compute/test_tenant_networks_client.py", line 15, in <module>
    from tempest_lib.tests import fake_auth_provider
ImportError: No module named tempest_lib.tests

0
]
tags: -worker-0
time: 2017-04-11 09:01:21.284148Z
tags: worker-0
test: unittest2.loader._FailedTest.tempest.tests.services.compute.test_tenant_usages_client
time: 2017-04-11 09:01:21.284248Z
failure: unittest2.loader._FailedTest.tempest.tests.services.compute.test_tenant_usages_client [ multipart
Content-Type: text/x-traceback;charset=utf8,language=python
traceback
289
Traceback (most recent call last):
ImportError: Failed to import test module: tempest.tests.services.compute.test_tenant_usages_client
Traceback (most recent call last):
  File "/root/tempest/.venv/lib/python2.7/site-packages/unittest2/loader.py", line 456, in _find_test_path
    module = self._get_module_from_name(name)
  File "/root/tempest/.venv/lib/python2.7/site-packages/unittest2/loader.py", line 395, in _get_module_from_name
    __import__(name)
  File "tempest/tests/services/compute/test_tenant_usages_client.py", line 15, in <module>
    from tempest_lib.tests import fake_auth_provider
ImportError: No module named tempest_lib.tests

0
]
tags: -worker-0
time: 2017-04-11 09:01:21.284584Z
tags: worker-0
test: unittest2.loader._FailedTest.tempest.tests.services.compute.test_volumes_client
time: 2017-04-11 09:01:21.284685Z
failure: unittest2.loader._FailedTest.tempest.tests.services.compute.test_volumes_client [ multipart
Content-Type: text/x-traceback;charset=utf8,language=python
traceback
262
Traceback (most recent call last):
ImportError: Failed to import test module: tempest.tests.services.compute.test_volumes_client
Traceback (most recent call last):
  File "/root/tempest/.venv/lib/python2.7/site-packages/unittest2/loader.py", line 456, in _find_test_path
    module = self._get_module_from_name(name)
  File "/root/tempest/.venv/lib/python2.7/site-packages/unittest2/loader.py", line 395, in _get_module_from_name
    __import__(name)
  File "tempest/tests/services/compute/test_volumes_client.py", line 17, in <module>
    from oslotest import mockpatch
ImportError: No module named oslotest

0
]
tags: -worker-0
time: 2017-04-11 09:01:21.285034Z
tags: worker-0
test: unittest2.loader._FailedTest.tempest.tests.stress.test_stress
time: 2017-04-11 09:01:21.285134Z
failure: unittest2.loader._FailedTest.tempest.tests.stress.test_stress [ multipart
Content-Type: text/x-traceback;charset=utf8,language=python
traceback
245
Traceback (most recent call last):
ImportError: Failed to import test module: tempest.tests.stress.test_stress
Traceback (most recent call last):
  File "/root/tempest/.venv/lib/python2.7/site-packages/unittest2/loader.py", line 456, in _find_test_path
    module = self._get_module_from_name(name)
  File "/root/tempest/.venv/lib/python2.7/site-packages/unittest2/loader.py", line 395, in _get_module_from_name
    __import__(name)
  File "tempest/tests/stress/test_stress.py", line 19, in <module>
    from tempest_lib import exceptions
ImportError: No module named tempest_lib

0
]
tags: -worker-0
time: 2017-04-11 09:01:21.285456Z
tags: worker-0
test: unittest2.loader._FailedTest.tempest.tests.stress.test_stressaction
time: 2017-04-11 09:01:21.285556Z
failure: unittest2.loader._FailedTest.tempest.tests.stress.test_stressaction [ multipart
Content-Type: text/x-traceback;charset=utf8,language=python
traceback
2C4
Traceback (most recent call last):
ImportError: Failed to import test module: tempest.tests.stress.test_stressaction
Traceback (most recent call last):
  File "/root/tempest/.venv/lib/python2.7/site-packages/unittest2/loader.py", line 456, in _find_test_path
    module = self._get_module_from_name(name)
  File "/root/tempest/.venv/lib/python2.7/site-packages/unittest2/loader.py", line 395, in _get_module_from_name
    __import__(name)
  File "tempest/tests/stress/test_stressaction.py", line 16, in <module>
    import tempest.stress.stressaction as stressaction
  File "tempest/stress/stressaction.py", line 21, in <module>
    from oslo_log import log as logging
ImportError: No module named oslo_log

0
]
tags: -worker-0
time: 2017-04-11 09:01:21.285888Z
tags: worker-0
test: unittest2.loader._FailedTest.tempest.tests.test_decorators
time: 2017-04-11 09:01:21.285990Z
failure: unittest2.loader._FailedTest.tempest.tests.test_decorators [ multipart
Content-Type: text/x-traceback;charset=utf8,language=python
traceback
221
Traceback (most recent call last):
ImportError: Failed to import test module: tempest.tests.test_decorators
Traceback (most recent call last):
  File "/root/tempest/.venv/lib/python2.7/site-packages/unittest2/loader.py", line 456, in _find_test_path
    module = self._get_module_from_name(name)
  File "/root/tempest/.venv/lib/python2.7/site-packages/unittest2/loader.py", line 395, in _get_module_from_name
    __import__(name)
  File "tempest/tests/test_decorators.py", line 17, in <module>
    import mock
ImportError: No module named mock

0
]
tags: -worker-0
time: 2017-04-11 09:01:21.286308Z
tags: worker-0
test: unittest2.loader._FailedTest.tempest.tests.test_dynamic_creds
time: 2017-04-11 09:01:21.286408Z
failure: unittest2.loader._FailedTest.tempest.tests.test_dynamic_creds [ multipart
Content-Type: text/x-traceback;charset=utf8,language=python
traceback
227
Traceback (most recent call last):
ImportError: Failed to import test module: tempest.tests.test_dynamic_creds
Traceback (most recent call last):
  File "/root/tempest/.venv/lib/python2.7/site-packages/unittest2/loader.py", line 456, in _find_test_path
    module = self._get_module_from_name(name)
  File "/root/tempest/.venv/lib/python2.7/site-packages/unittest2/loader.py", line 395, in _get_module_from_name
    __import__(name)
  File "tempest/tests/test_dynamic_creds.py", line 15, in <module>
    import mock
ImportError: No module named mock

0
]
tags: -worker-0
time: 2017-04-11 09:01:21.286723Z
tags: worker-0
test: unittest2.loader._FailedTest.tempest.tests.test_glance_http
time: 2017-04-11 09:01:21.286823Z
failure: unittest2.loader._FailedTest.tempest.tests.test_glance_http [ multipart
Content-Type: text/x-traceback;charset=utf8,language=python
traceback
223
Traceback (most recent call last):
ImportError: Failed to import test module: tempest.tests.test_glance_http
Traceback (most recent call last):
  File "/root/tempest/.venv/lib/python2.7/site-packages/unittest2/loader.py", line 456, in _find_test_path
    module = self._get_module_from_name(name)
  File "/root/tempest/.venv/lib/python2.7/site-packages/unittest2/loader.py", line 395, in _get_module_from_name
    __import__(name)
  File "tempest/tests/test_glance_http.py", line 18, in <module>
    import mock
ImportError: No module named mock

0
]
tags: -worker-0
time: 2017-04-11 09:01:21.287163Z
tags: worker-0
test: unittest2.loader._FailedTest.tempest.tests.test_hacking
time: 2017-04-11 09:01:21.287261Z
failure: unittest2.loader._FailedTest.tempest.tests.test_hacking [ multipart
Content-Type: text/x-traceback;charset=utf8,language=python
traceback
27B
Traceback (most recent call last):
ImportError: Failed to import test module: tempest.tests.test_hacking
Traceback (most recent call last):
  File "/root/tempest/.venv/lib/python2.7/site-packages/unittest2/loader.py", line 456, in _find_test_path
    module = self._get_module_from_name(name)
  File "/root/tempest/.venv/lib/python2.7/site-packages/unittest2/loader.py", line 395, in _get_module_from_name
    __import__(name)
  File "tempest/tests/test_hacking.py", line 15, in <module>
    from tempest.hacking import checks
  File "tempest/hacking/checks.py", line 18, in <module>
    import pep8
ImportError: No module named pep8

0
]
tags: -worker-0
time: 2017-04-11 09:01:21.287581Z
tags: worker-0
test: unittest2.loader._FailedTest.tempest.tests.test_list_tests
time: 2017-04-11 09:01:21.287680Z
failure: unittest2.loader._FailedTest.tempest.tests.test_list_tests [ multipart
Content-Type: text/x-traceback;charset=utf8,language=python
traceback
279
Traceback (most recent call last):
ImportError: Failed to import test module: tempest.tests.test_list_tests
Traceback (most recent call last):
  File "/root/tempest/.venv/lib/python2.7/site-packages/unittest2/loader.py", line 456, in _find_test_path
    module = self._get_module_from_name(name)
  File "/root/tempest/.venv/lib/python2.7/site-packages/unittest2/loader.py", line 395, in _get_module_from_name
    __import__(name)
  File "tempest/tests/test_list_tests.py", line 20, in <module>
    from tempest.tests import base
  File "tempest/tests/base.py", line 15, in <module>
    import mock
ImportError: No module named mock

0
]
tags: -worker-0
time: 2017-04-11 09:01:21.336534Z
tags: worker-0
test: unittest2.loader._FailedTest.tempest.tests.test_negative_rest_client
time: 2017-04-11 09:01:21.336664Z
failure: unittest2.loader._FailedTest.tempest.tests.test_negative_rest_client [ multipart
Content-Type: text/x-traceback;charset=utf8,language=python
traceback
24C
Traceback (most recent call last):
ImportError: Failed to import test module: tempest.tests.test_negative_rest_client
Traceback (most recent call last):
  File "/root/tempest/.venv/lib/python2.7/site-packages/unittest2/loader.py", line 456, in _find_test_path
    module = self._get_module_from_name(name)
  File "/root/tempest/.venv/lib/python2.7/site-packages/unittest2/loader.py", line 395, in _get_module_from_name
    __import__(name)
  File "tempest/tests/test_negative_rest_client.py", line 19, in <module>
    from oslotest import mockpatch
ImportError: No module named oslotest

0
]
tags: -worker-0
time: 2017-04-11 09:01:21.337063Z
tags: worker-0
test: unittest2.loader._FailedTest.tempest.tests.test_tempest_plugin
time: 2017-04-11 09:01:21.337170Z
failure: unittest2.loader._FailedTest.tempest.tests.test_tempest_plugin [ multipart
Content-Type: text/x-traceback;charset=utf8,language=python
traceback
2C9
Traceback (most recent call last):
ImportError: Failed to import test module: tempest.tests.test_tempest_plugin
Traceback (most recent call last):
  File "/root/tempest/.venv/lib/python2.7/site-packages/unittest2/loader.py", line 456, in _find_test_path
    module = self._get_module_from_name(name)
  File "/root/tempest/.venv/lib/python2.7/site-packages/unittest2/loader.py", line 395, in _get_module_from_name
    __import__(name)
  File "tempest/tests/test_tempest_plugin.py", line 16, in <module>
    from tempest.test_discover import plugins
  File "tempest/test_discover/plugins.py", line 20, in <module>
    from tempest_lib.common.utils import misc
ImportError: No module named tempest_lib.common.utils

0
]
tags: -worker-0
time: 2017-04-11 09:01:21.337507Z
tags: worker-0
test: unittest2.loader._FailedTest.tempest.tests.test_wrappers
time: 2017-04-11 09:01:21.337611Z
failure: unittest2.loader._FailedTest.tempest.tests.test_wrappers [ multipart
Content-Type: text/x-traceback;charset=utf8,language=python
traceback
275
Traceback (most recent call last):
ImportError: Failed to import test module: tempest.tests.test_wrappers
Traceback (most recent call last):
  File "/root/tempest/.venv/lib/python2.7/site-packages/unittest2/loader.py", line 456, in _find_test_path
    module = self._get_module_from_name(name)
  File "/root/tempest/.venv/lib/python2.7/site-packages/unittest2/loader.py", line 395, in _get_module_from_name
    __import__(name)
  File "tempest/tests/test_wrappers.py", line 22, in <module>
    from tempest.tests import base
  File "tempest/tests/base.py", line 15, in <module>
    import mock
ImportError: No module named mock

0
]
tags: -worker-0
